local variable 'demo' referenced before assignment
local variable 'demo' referenced before assignment
local variable 'demo' referenced before assignment
local variable 'demo' referenced before assignment
local variable 'demo' referenced before assignment
local variable 'demo' referenced before assignment
local variable 'demo' referenced before assignment
local variable 'demo' referenced before assignment
local variable 'demo' referenced before assignment
local variable 'demo' referenced before assignment
local variable 'demo' referenced before assignment
local variable 'demo' referenced before assignment
local variable 'demo' referenced before assignment
local variable 'demo' referenced before assignment
local variable 'demo' referenced before assignment
local variable 'demo' referenced before assignment
local variable 'demo' referenced before assignment
local variable 'demo' referenced before assignment
local variable 'demo' referenced before assignment
local variable 'demo' referenced before assignment
local variable 'demo' referenced before assignment
local variable 'demo' referenced before assignment
local variable 'demo' referenced before assignment
local variable 'demo' referenced before assignment
local variable 'demo' referenced before assignment
local variable 'demo' referenced before assignment
Exception on /getClasses [POST]
Traceback (most recent call last):
  File "/usr/local/lib/python2.7/dist-packages/flask/app.py", line 1988, in wsgi_app
    response = self.full_dispatch_request()
  File "/usr/local/lib/python2.7/dist-packages/flask/app.py", line 1641, in full_dispatch_request
    rv = self.handle_user_exception(e)
  File "/usr/local/lib/python2.7/dist-packages/flask/app.py", line 1544, in handle_user_exception
    reraise(exc_type, exc_value, tb)
  File "/usr/local/lib/python2.7/dist-packages/flask/app.py", line 1639, in full_dispatch_request
    rv = self.dispatch_request()
  File "/usr/local/lib/python2.7/dist-packages/flask/app.py", line 1625, in dispatch_request
    return self.view_functions[rule.endpoint](**req.view_args)
  File "/usr/local/lib/python2.7/dist-packages/flask_cors/decorator.py", line 128, in wrapped_function
    resp = make_response(f(*args, **kwargs))
  File "/home/ubuntu/plecprepShoppingCart/server.py", line 30, in getClasses
    classes = data[prof].keys()
KeyError: 'offner'
local variable 'demo' referenced before assignment
local variable 'demo' referenced before assignment
file_cache is unavailable when using oauth2client >= 4.0.0
Traceback (most recent call last):
  File "/usr/local/lib/python2.7/dist-packages/googleapiclient/discovery_cache/__init__.py", line 41, in autodetect
    from . import file_cache
  File "/usr/local/lib/python2.7/dist-packages/googleapiclient/discovery_cache/file_cache.py", line 41, in <module>
    'file_cache is unavailable when using oauth2client >= 4.0.0')
ImportError: file_cache is unavailable when using oauth2client >= 4.0.0
file_cache is unavailable when using oauth2client >= 4.0.0
Traceback (most recent call last):
  File "/usr/local/lib/python2.7/dist-packages/googleapiclient/discovery_cache/__init__.py", line 41, in autodetect
    from . import file_cache
  File "/usr/local/lib/python2.7/dist-packages/googleapiclient/discovery_cache/file_cache.py", line 41, in <module>
    'file_cache is unavailable when using oauth2client >= 4.0.0')
ImportError: file_cache is unavailable when using oauth2client >= 4.0.0
file_cache is unavailable when using oauth2client >= 4.0.0
Traceback (most recent call last):
  File "/usr/local/lib/python2.7/dist-packages/googleapiclient/discovery_cache/__init__.py", line 41, in autodetect
    from . import file_cache
  File "/usr/local/lib/python2.7/dist-packages/googleapiclient/discovery_cache/file_cache.py", line 41, in <module>
    'file_cache is unavailable when using oauth2client >= 4.0.0')
ImportError: file_cache is unavailable when using oauth2client >= 4.0.0
file_cache is unavailable when using oauth2client >= 4.0.0
Traceback (most recent call last):
  File "/usr/local/lib/python2.7/dist-packages/googleapiclient/discovery_cache/__init__.py", line 41, in autodetect
    from . import file_cache
  File "/usr/local/lib/python2.7/dist-packages/googleapiclient/discovery_cache/file_cache.py", line 41, in <module>
    'file_cache is unavailable when using oauth2client >= 4.0.0')
ImportError: file_cache is unavailable when using oauth2client >= 4.0.0
file_cache is unavailable when using oauth2client >= 4.0.0
Traceback (most recent call last):
  File "/usr/local/lib/python2.7/dist-packages/googleapiclient/discovery_cache/__init__.py", line 41, in autodetect
    from . import file_cache
  File "/usr/local/lib/python2.7/dist-packages/googleapiclient/discovery_cache/file_cache.py", line 41, in <module>
    'file_cache is unavailable when using oauth2client >= 4.0.0')
ImportError: file_cache is unavailable when using oauth2client >= 4.0.0
file_cache is unavailable when using oauth2client >= 4.0.0
Traceback (most recent call last):
  File "/usr/local/lib/python2.7/dist-packages/googleapiclient/discovery_cache/__init__.py", line 41, in autodetect
    from . import file_cache
  File "/usr/local/lib/python2.7/dist-packages/googleapiclient/discovery_cache/file_cache.py", line 41, in <module>
    'file_cache is unavailable when using oauth2client >= 4.0.0')
ImportError: file_cache is unavailable when using oauth2client >= 4.0.0
file_cache is unavailable when using oauth2client >= 4.0.0
Traceback (most recent call last):
  File "/usr/local/lib/python2.7/dist-packages/googleapiclient/discovery_cache/__init__.py", line 41, in autodetect
    from . import file_cache
  File "/usr/local/lib/python2.7/dist-packages/googleapiclient/discovery_cache/file_cache.py", line 41, in <module>
    'file_cache is unavailable when using oauth2client >= 4.0.0')
ImportError: file_cache is unavailable when using oauth2client >= 4.0.0
file_cache is unavailable when using oauth2client >= 4.0.0
Traceback (most recent call last):
  File "/usr/local/lib/python2.7/dist-packages/googleapiclient/discovery_cache/__init__.py", line 41, in autodetect
    from . import file_cache
  File "/usr/local/lib/python2.7/dist-packages/googleapiclient/discovery_cache/file_cache.py", line 41, in <module>
    'file_cache is unavailable when using oauth2client >= 4.0.0')
ImportError: file_cache is unavailable when using oauth2client >= 4.0.0
